<?xml version="1.0" ?><robot name="NIFTi"><link name="rear_right_box"/><joint name="rear_right_box_j"
  type="fixed"><parent link="base_link"/><child link="rear_right_box"/><origin rpy="0
  0 0" xyz="-0.3175 -0.1215 0.185"/></joint><link name="os_sensor"><visual><geometry><mesh
  filename="/home/robert/catkin_ws/src/tradr-resources/nifti_robot_description/meshes/ouster-os0.dae"/></geometry></visual><collision><origin
  rpy="0 0 0" xyz="0 0 0.03675"/><geometry><cylinder length="0.0735" radius="0.0435"/></geometry></collision><inertial><mass
  value="0.5"/><origin xyz="0 0 0.03675"/><inertia ixx="0.0004616249999999999" ixy="0.0"
  ixz="0.0" iyy="0.0004616249999999999" iyz="0.0" izz="0.00047306249999999996"/></inertial></link><joint
  name="ouster_holder_j" type="fixed"><parent link="omnicam_top"/><child link="ouster_holder"/><origin
  rpy="0.0 0.0 0.0" xyz="0.08 0.0 0.005"/></joint><!-- workaround for https://github.com/osrf/sdformat/issues/378
  --><gazebo reference="ouster_holder_j"><preserveFixedJoint>true</preserveFixedJoint></gazebo><joint
  name="ouster_base_j" type="fixed"><parent link="ouster_holder"/><child link="ouster_base"/><origin
  rpy="0.0 0.175 0.0" xyz="0.0 0.0 0.0"/></joint><!-- workaround for https://github.com/osrf/sdformat/issues/378
  --><gazebo reference="ouster_base_j"><preserveFixedJoint>true</preserveFixedJoint></gazebo><joint
  name="ouster_j" type="fixed"><parent link="ouster_base"/><child link="os_sensor"/><origin
  rpy="0.01 0.01 0.75" xyz="0.0 0.0 0.006"/></joint><!-- workaround for https://github.com/osrf/sdformat/issues/378
  --><gazebo reference="ouster_j"><preserveFixedJoint>true</preserveFixedJoint></gazebo><link
  name="ouster_base"><inertial><origin rpy="0 0 0" xyz="0 0 0"/><mass value="1e-5"/><inertia
  ixx="1e-3" ixy="1e-6" ixz="1e-6" iyy="1e-3" iyz="1e-6" izz="1e-3"/></inertial></link><link
  name="ouster_holder"><visual><origin xyz="0 0 0"/><geometry><mesh filename="/home/robert/catkin_ws/src/tradr-resources/nifti_robot_description/meshes/ouster_holder_ladybug.dae"/></geometry></visual><inertial><mass
  value="0.2"/><origin xyz="0 0 -0.01"/><inertia ixx="0.0002516666666666667" ixy="0.0"
  ixz="0.0" iyy="0.0002516666666666667" iyz="0.0" izz="0.0004900000000000001"/></inertial></link><link
  name="base_link"><visual><origin rpy="0 0 0" xyz="0 0 0"/><geometry><mesh filename="/home/robert/catkin_ws/src/tradr-resources/nifti_robot_description/meshes/body_2021.dae"
  scale="1.0 1.0 1.0"/></geometry></visual><collision><origin rpy="0 0 0" xyz="0.000000
  0 0.1395"/><geometry><box size="0.635000 0.243000 0.10799999999999998"/></geometry></collision><collision><origin
  rpy="0 0 0" xyz="0 0.135 0.09"/><geometry><box size="0.055 0.040 0.08"/></geometry></collision><collision><origin
  rpy="0 0 0" xyz="0 0.155 0.013"/><geometry><box size="0.055 0.020 0.075"/></geometry></collision><collision><origin
  rpy="0 0 0" xyz="0 -0.135 0.09"/><geometry><box size="0.055 0.040 0.08"/></geometry></collision><collision><origin
  rpy="0 0 0" xyz="0 -0.155 0.013"/><geometry><box size="0.055 0.020 0.075"/></geometry></collision><collision><origin
  rpy="0 0 0" xyz="0 0 0.0655"/><geometry><box size="0.565 0.243000 0.035000"/></geometry></collision><collision><origin
  rpy="1.5707963267948966 0 0" xyz="0.2825 0 0.083"/><geometry><cylinder length="0.243000"
  radius="0.035035"/></geometry></collision><collision><origin rpy="1.5707963267948966
  0 0" xyz="-0.2825 0 0.083"/><geometry><cylinder length="0.243000" radius="0.035035"/></geometry></collision><collision
  name="big_collision_box"><origin rpy="0 0 0" xyz="0.0 0 0.255"/><geometry><box size="0.6
  0.5 0.35"/></geometry></collision><inertial><origin rpy="0 0 0" xyz="-0.034 0 0.142"/><mass
  value="6.746"/><inertia ixx="0.0069904" ixy="0.00012271" ixz="-4.2725e-05" iyy="0.02129"
  iyz="-0.00010522" izz="0.025519"/></inertial></link><link name="battery"><visual><origin
  rpy="0 0 0" xyz="0 0 0"/><geometry><mesh filename="/home/robert/catkin_ws/src/tradr-resources/nifti_robot_description/meshes/battery.dae"
  scale="1.0 1.0 1.0"/></geometry></visual><collision><origin rpy="0 0 0" xyz="0 0
  0.0410"/><geometry><box size="0.1450 0.1350 0.0820"/></geometry></collision><inertial><origin
  rpy="0 0 0" xyz="0 0 0.041"/><mass value="3.18"/><inertia ixx="0.0020793" ixy="0.0"
  ixz="0.0" iyy="0.0023127" iyz="0.0" izz="0.0032712"/></inertial></link><joint name="battery_j"
  type="fixed"><parent link="base_link"/><child link="battery"/><origin rpy="0 1.5707963267948966
  0" xyz="-0.105 0 0.12"/></joint><link name="battery_cover"><visual><origin xyz="0
  0 0.0335"/><geometry><box size="0.13 0.185 0.067"/></geometry><material name="body_color"><color
  rgba="0 0.3686274509803922 0.7215686274509804 1.0"/></material></visual><collision><origin
  xyz="0 0 0.0335"/><geometry><box size="0.13 0.185 0.067"/></geometry></collision></link><joint
  name="battery_cover_j" type="fixed"><parent link="rear_right_box"/><child link="battery_cover"/><origin
  rpy="0 0 0" xyz="0.225 0.1215 0.0"/></joint><link name="top_box"><visual><origin
  rpy="0 0 0" xyz="0 0 0"/><geometry><mesh filename="/home/robert/catkin_ws/src/tradr-resources/nifti_robot_description/meshes/top_box_2021_ladybug.dae"
  scale="1.0 1.0 1.0"/></geometry></visual><collision><origin rpy="0 0 0" xyz="0 0
  0.0485"/><geometry><box size="0.18 0.233 0.097"/></geometry></collision><collision><origin
  rpy="0 0 0" xyz="-0.04 0.09 0.0690"/><geometry><box size="0.0440 0.0440 0.01303"/></geometry></collision><collision><origin
  rpy="0 0 0" xyz="0.01474 -0.08352 0.07996"/><geometry><box size="0.03732 0.03523
  0.03489"/></geometry></collision><visual><origin rpy="0.0 0 0" xyz="-0.1 -0.1 0.135"/><geometry><cylinder
  length="0.11" radius="0.01"/></geometry><material name="black_color"><color rgba="0.0
  0.0 0.0 1.0"/></material></visual><collision><origin rpy="0.0 0 0" xyz="-0.1 -0.1
  0.135"/><geometry><cylinder length="0.11" radius="0.01"/></geometry></collision><visual><origin
  rpy="0.0 0 0" xyz="0.1 0.047 0.085"/><geometry><cylinder length="0.13" radius="0.01"/></geometry><material
  name="black_color"><color rgba="0.0 0.0 0.0 1.0"/></material></visual><collision><origin
  rpy="0.0 0 0" xyz="0.1 0.047 0.085"/><geometry><cylinder length="0.13" radius="0.01"/></geometry></collision><visual><origin
  rpy="0.0 0 0" xyz="0.1 -0.047 0.085"/><geometry><cylinder length="0.13" radius="0.01"/></geometry><material
  name="black_color"><color rgba="0.0 0.0 0.0 1.0"/></material></visual><collision><origin
  rpy="0.0 0 0" xyz="0.1 -0.047 0.085"/><geometry><cylinder length="0.13" radius="0.01"/></geometry></collision><inertial><origin
  rpy="0 0 0" xyz="0 0 0.041"/><mass value="0.24"/><inertia ixx="0.0026136" ixy="0.0"
  ixz="0.0" iyy="0.0049426" iyz="0.0" izz="0.0070334"/></inertial></link><joint name="top_box_j"
  type="fixed"><parent link="rear_right_box"/><child link="top_box"/><origin rpy="0
  0 0" xyz="0.41400000000000003 0.1215 0.0"/></joint><link name="antenna"><visual><origin
  rpy="0 0 0" xyz="0 0 0"/><geometry><mesh filename="/home/robert/catkin_ws/src/tradr-resources/nifti_robot_description/meshes/antenna.dae"
  scale="1.0 1.0 1.0"/></geometry></visual><collision><origin rpy="0 1.5707963267948966
  0" xyz="-0.01864 0 0"/><geometry><cylinder length="0.03718" radius="0.008"/></geometry></collision><collision><origin
  rpy="0 0 0" xyz="-0.030 0 0.19053"/><geometry><cylinder length="0.38107" radius="0.008"/></geometry></collision><inertial><origin
  rpy="0 0 0" xyz="-0.022 0.0203 0.02917"/><mass value="0.56"/><inertia ixx="0.004878"
  ixy="-6.2341e-07" ixz="-7.4538e-07" iyy="0.00090164" iyz="-0.00014394" izz="0.0042946"/></inertial></link><joint
  name="antenna_j" type="fixed"><parent link="rear_right_box"/><child link="antenna"/><origin
  rpy="0 0 0" xyz="0.055 0.215 0.0"/></joint><link name="gps_antenna"><visual><origin
  rpy="0 0 0" xyz="0 0 0.4"/><geometry><cylinder length="0.01" radius="0.05"/></geometry><material
  name="aluminium"><color rgba="0.8 0.8 0.8 1"/></material></visual><visual><origin
  rpy="0 0 0" xyz="0 0 0.2"/><geometry><cylinder length="0.4" radius="0.03"/></geometry><material
  name="aluminium"><color rgba="0.8 0.8 0.8 1"/></material></visual><collision><origin
  rpy="0 0 0" xyz="0 0 0.4"/><geometry><cylinder length="0.01" radius="0.1"/></geometry></collision><collision><origin
  rpy="0 0 0" xyz="0 0 0.2"/><geometry><cylinder length="0.4" radius="0.09"/></geometry></collision><inertial><origin
  rpy="0 0 0" xyz="-0.022 0.0203 0.02917"/><mass value="0.1"/><inertia ixx="0.004878"
  ixy="-6.2341e-07" ixz="-7.4538e-07" iyy="0.00090164" iyz="-0.00014394" izz="0.0042946"/></inertial></link><joint
  name="gps_antenna_j" type="fixed"><parent link="rear_right_box"/><child link="gps_antenna"/><origin
  rpy="0 0 0" xyz="0.055 0.1 0.0"/></joint><link name="left_track"><visual><origin
  rpy="1.57 0 1.57" xyz="0 0 -0.0705"/><geometry><mesh filename="/home/robert/catkin_ws/src/tradr-resources/nifti_robot_description/meshes/bogie.dae"
  scale="1.0 1.0 1.0"/></geometry></visual><collision><origin rpy="1.5707963267948966
  0 1.5707963267948966" xyz="0 0 0.01855"/><geometry><box size="0.097000 0.178 0.500000"/></geometry></collision><collision><origin
  rpy="1.5707963267948966 0 0" xyz="0.25 -0.015 0.01855"/><geometry><cylinder length="0.112"
  radius="0.089000"/></geometry></collision><collision><origin rpy="1.5707963267948966
  0 0" xyz="-0.25 0 0.01855"/><geometry><cylinder length="0.097000" radius="0.089000"/></geometry></collision><inertial><origin
  rpy="0 0 0" xyz="0 0 0.0141"/><mass value="6.06"/><inertia ixx="0.002731" ixy="0.0"
  ixz="0.0" iyy="0.032554" iyz="1.5e-05" izz="0.031391"/></inertial></link><joint
  name="left_track_j" type="revolute"><parent link="base_link"/><child link="left_track"/><axis
  xyz="0 1 0"/><origin rpy="0 0.0 0" xyz="0 0.1985 0"/><limit effort="0" lower="-0.7"
  upper="0.7" velocity="4"/></joint><link name="right_track"><visual><origin rpy="1.57
  0 -1.57" xyz="0 0 -0.0705"/><geometry><mesh filename="/home/robert/catkin_ws/src/tradr-resources/nifti_robot_description/meshes/bogie.dae"
  scale="1.0 1.0 1.0"/></geometry></visual><collision><origin rpy="1.5707963267948966
  0 1.5707963267948966" xyz="0 0 0.01855"/><geometry><box size="0.097000 0.178 0.500000"/></geometry></collision><collision><origin
  rpy="1.5707963267948966 0 0" xyz="0.25 0.015 0.01855"/><geometry><cylinder length="0.112"
  radius="0.089000"/></geometry></collision><collision><origin rpy="1.5707963267948966
  0 0" xyz="-0.25 0 0.01855"/><geometry><cylinder length="0.097000" radius="0.089000"/></geometry></collision><inertial><origin
  rpy="0 0 0" xyz="0 0 0.0141"/><mass value="6.06"/><inertia ixx="0.002731" ixy="0.0"
  ixz="0.0" iyy="0.032554" iyz="1.5e-05" izz="0.031391"/></inertial></link><joint
  name="right_track_j" type="revolute"><parent link="base_link"/><child link="right_track"/><axis
  xyz="0 1 0"/><origin rpy="0 0.0 0" xyz="0 -0.1985 0"/><mimic joint="left_track_j"
  multiplier="-1"/><limit effort="0" lower="-0.7" upper="0.7" velocity="4"/></joint><link
  name="front_left_flipper"><visual><origin rpy="3.32575 0 1.5707963267948966" xyz="0
  0 0"/><geometry><mesh filename="/home/robert/catkin_ws/src/tradr-resources/nifti_robot_description/meshes/flipper.dae"
  scale="1.0 1.0 1.0"/></geometry></visual><collision name="front_left_flipper_collision_large_wheel"><origin
  rpy="1.5707963267948966 0 0" xyz="0 -0.0 0"/><geometry><cylinder length="0.04981"
  radius="0.089000"/></geometry></collision><collision name="front_left_flipper_collision_small_wheel"><origin
  rpy="1.5707963267948966 0 0" xyz="0.33 -0.0 0.0"/><geometry><cylinder length="0.04981"
  radius="0.043500000000000004"/></geometry></collision><collision name="front_left_flipper_collision_top_bar"><origin
  rpy="0 0.184162095 0.0" xyz="0.165 -0.0 0.0325"/><geometry><box size="0.330000 0.04981
  0.0825"/></geometry></collision><collision name="front_left_flipper_collision_bottom_bar"><origin
  rpy="0 -0.184162095 0.0" xyz="0.165 -0.0 -0.0325"/><geometry><box size="0.330000
  0.04981 0.0825"/></geometry></collision><collision name="front_left_flipper_collision_middle_bar"><origin
  rpy="0 -0.02 0.0" xyz="0.166 -0.0 0.004"/><geometry><box size="0.20 0.04981 0.07"/></geometry></collision><inertial><origin
  rpy="0 0 0" xyz="0.08 0 0.0"/><mass value="0.75"/><inertia ixx="0.0017491" ixy="2.8512e-07"
  ixz="0.0018277" iyy="0.012277" iyz="-3.6288e-07" izz="0.010941"/></inertial><sensor
  name="front_left_flipper_contact" type="contact"><contact><collision>front_left_flipper_collision</collision><collision>front_left_flipper_collision_large_wheel</collision><collision>front_left_flipper_collision_small_wheel</collision><collision>front_left_flipper_collision_top_bar</collision><collision>front_left_flipper_collision_bottom_bar</collision><collision>front_left_flipper_collision_middle_bar</collision></contact></sensor></link><joint
  name="front_left_flipper_j" type="continuous"><parent link="left_track"/><child
  link="front_left_flipper"/><axis xyz="0 1 0"/><origin rpy="0 0.193732 0" xyz="0.25
  0.0735 0.0195"/></joint><link name="front_left_flipper_end_point"/><joint name="front_left_flipper_end_point_j"
  type="fixed"><parent link="front_left_flipper"/><child link="front_left_flipper_end_point"/><origin
  rpy="0 0.193732 0" xyz="0.3476 0 0"/></joint><link name="front_right_flipper"><visual><origin
  rpy="3.32575 0 -1.5707963267948966" xyz="0 0 0"/><geometry><mesh filename="/home/robert/catkin_ws/src/tradr-resources/nifti_robot_description/meshes/flipper.dae"
  scale="1.0 1.0 1.0"/></geometry></visual><collision name="front_right_flipper_collision_large_wheel"><origin
  rpy="1.5707963267948966 0 0" xyz="0 0.0 0"/><geometry><cylinder length="0.04981"
  radius="0.089000"/></geometry></collision><collision name="front_right_flipper_collision_small_wheel"><origin
  rpy="1.5707963267948966 0 0" xyz="-0.33 0.0 0.0"/><geometry><cylinder length="0.04981"
  radius="0.043500000000000004"/></geometry></collision><collision name="front_right_flipper_collision_top_bar"><origin
  rpy="0 0.184162095 3.141592653589793" xyz="-0.165 0.0 0.0325"/><geometry><box size="0.330000
  0.04981 0.0825"/></geometry></collision><collision name="front_right_flipper_collision_bottom_bar"><origin
  rpy="0 -0.184162095 3.141592653589793" xyz="-0.165 0.0 -0.0325"/><geometry><box
  size="0.330000 0.04981 0.0825"/></geometry></collision><collision name="front_right_flipper_collision_middle_bar"><origin
  rpy="0 -0.02 3.141592653589793" xyz="-0.166 0.0 0.004"/><geometry><box size="0.20
  0.04981 0.07"/></geometry></collision><inertial><origin rpy="0 0 0" xyz="-0.08 0
  0.0"/><mass value="0.75"/><inertia ixx="0.0017491" ixy="2.8512e-07" ixz="0.0018277"
  iyy="0.012277" iyz="-3.6288e-07" izz="0.010941"/></inertial><sensor name="front_right_flipper_contact"
  type="contact"><contact><collision>front_right_flipper_collision</collision><collision>front_right_flipper_collision_large_wheel</collision><collision>front_right_flipper_collision_small_wheel</collision><collision>front_right_flipper_collision_top_bar</collision><collision>front_right_flipper_collision_bottom_bar</collision><collision>front_right_flipper_collision_middle_bar</collision></contact></sensor></link><joint
  name="front_right_flipper_j" type="continuous"><parent link="right_track"/><child
  link="front_right_flipper"/><axis xyz="0 1 0"/><origin rpy="0 -2.9478606535897933
  0" xyz="0.25 -0.0735 0.0195"/></joint><link name="front_right_flipper_end_point"/><joint
  name="front_right_flipper_end_point_j" type="fixed"><parent link="front_right_flipper"/><child
  link="front_right_flipper_end_point"/><origin rpy="0 0.193732 0" xyz="-0.3476 0
  0"/></joint><link name="rear_left_flipper"><visual><origin rpy="3.32575 0 1.5707963267948966"
  xyz="0 0 0"/><geometry><mesh filename="/home/robert/catkin_ws/src/tradr-resources/nifti_robot_description/meshes/flipper.dae"
  scale="1.0 1.0 1.0"/></geometry></visual><collision name="rear_left_flipper_collision_large_wheel"><origin
  rpy="1.5707963267948966 0 0" xyz="0 -0.0 0"/><geometry><cylinder length="0.04981"
  radius="0.089000"/></geometry></collision><collision name="rear_left_flipper_collision_small_wheel"><origin
  rpy="1.5707963267948966 0 0" xyz="0.33 -0.0 0.0"/><geometry><cylinder length="0.04981"
  radius="0.029"/></geometry></collision><collision name="rear_left_flipper_collision_top_bar"><origin
  rpy="0 0.184162095 0.0" xyz="0.165 -0.0 0.0325"/><geometry><box size="0.330000 0.04981
  0.055"/></geometry></collision><collision name="rear_left_flipper_collision_bottom_bar"><origin
  rpy="0 -0.184162095 0.0" xyz="0.165 -0.0 -0.0325"/><geometry><box size="0.330000
  0.04981 0.055"/></geometry></collision><collision name="rear_left_flipper_collision_middle_bar"><origin
  rpy="0 -0.02 0.0" xyz="0.166 -0.0 0.004"/><geometry><box size="0.20 0.04981 0.07"/></geometry></collision><inertial><origin
  rpy="0 0 0" xyz="0.08 0 0.0"/><mass value="0.75"/><inertia ixx="0.0017491" ixy="2.8512e-07"
  ixz="0.0018277" iyy="0.012277" iyz="-3.6288e-07" izz="0.010941"/></inertial><sensor
  name="rear_left_flipper_contact" type="contact"><contact><collision>rear_left_flipper_collision</collision><collision>rear_left_flipper_collision_large_wheel</collision><collision>rear_left_flipper_collision_small_wheel</collision><collision>rear_left_flipper_collision_top_bar</collision><collision>rear_left_flipper_collision_bottom_bar</collision><collision>rear_left_flipper_collision_middle_bar</collision></contact></sensor></link><joint
  name="rear_left_flipper_j" type="continuous"><parent link="left_track"/><child link="rear_left_flipper"/><axis
  xyz="0 1 0"/><origin rpy="0 2.9478606535897933 0" xyz="-0.25 0.0735 0.0195"/></joint><link
  name="rear_left_flipper_end_point"/><joint name="rear_left_flipper_end_point_j"
  type="fixed"><parent link="rear_left_flipper"/><child link="rear_left_flipper_end_point"/><origin
  rpy="0 0.193732 0" xyz="0.3476 0 0"/></joint><link name="rear_right_flipper"><visual><origin
  rpy="3.32575 0 -1.5707963267948966" xyz="0 0 0"/><geometry><mesh filename="/home/robert/catkin_ws/src/tradr-resources/nifti_robot_description/meshes/flipper.dae"
  scale="1.0 1.0 1.0"/></geometry></visual><collision name="rear_right_flipper_collision_large_wheel"><origin
  rpy="1.5707963267948966 0 0" xyz="0 0.0 0"/><geometry><cylinder length="0.04981"
  radius="0.089000"/></geometry></collision><collision name="rear_right_flipper_collision_small_wheel"><origin
  rpy="1.5707963267948966 0 0" xyz="-0.33 0.0 0.0"/><geometry><cylinder length="0.04981"
  radius="0.029"/></geometry></collision><collision name="rear_right_flipper_collision_top_bar"><origin
  rpy="0 0.184162095 3.141592653589793" xyz="-0.165 0.0 0.0325"/><geometry><box size="0.330000
  0.04981 0.055"/></geometry></collision><collision name="rear_right_flipper_collision_bottom_bar"><origin
  rpy="0 -0.184162095 3.141592653589793" xyz="-0.165 0.0 -0.0325"/><geometry><box
  size="0.330000 0.04981 0.055"/></geometry></collision><collision name="rear_right_flipper_collision_middle_bar"><origin
  rpy="0 -0.02 3.141592653589793" xyz="-0.166 0.0 0.004"/><geometry><box size="0.20
  0.04981 0.07"/></geometry></collision><inertial><origin rpy="0 0 0" xyz="-0.08 0
  0.0"/><mass value="0.75"/><inertia ixx="0.0017491" ixy="2.8512e-07" ixz="0.0018277"
  iyy="0.012277" iyz="-3.6288e-07" izz="0.010941"/></inertial><sensor name="rear_right_flipper_contact"
  type="contact"><contact><collision>rear_right_flipper_collision</collision><collision>rear_right_flipper_collision_large_wheel</collision><collision>rear_right_flipper_collision_small_wheel</collision><collision>rear_right_flipper_collision_top_bar</collision><collision>rear_right_flipper_collision_bottom_bar</collision><collision>rear_right_flipper_collision_middle_bar</collision></contact></sensor></link><joint
  name="rear_right_flipper_j" type="continuous"><parent link="right_track"/><child
  link="rear_right_flipper"/><axis xyz="0 1 0"/><origin rpy="0 -0.193732 0" xyz="-0.25
  -0.0735 0.0195"/></joint><link name="rear_right_flipper_end_point"/><joint name="rear_right_flipper_end_point_j"
  type="fixed"><parent link="rear_right_flipper"/><child link="rear_right_flipper_end_point"/><origin
  rpy="0 0.193732 0" xyz="-0.3476 0 0"/></joint><link name="imu"><inertial><origin
  rpy="0 0 0" xyz="0 0 0"/><mass value="1e-5"/><inertia ixx="1e-3" ixy="1e-6" ixz="1e-6"
  iyy="1e-3" iyz="1e-6" izz="1e-3"/></inertial></link><joint name="imu_j" type="fixed"><parent
  link="base_link"/><child link="imu"/><origin rpy="3.141592653589793 0 -1.5707963267948966"
  xyz="0 0 0.1500"/></joint><link name="omnicam"><visual><origin rpy="0 0 0" xyz="0
  0 0"/><geometry><mesh filename="/home/robert/catkin_ws/src/tradr-resources/nifti_robot_description/meshes/omnicam.dae"
  scale="1.0 1.0 1.0"/></geometry></visual><collision><origin rpy="0 0 0" xyz="-0.003
  -0.0015 0.003"/><geometry><cylinder length="0.137" radius="0.068"/></geometry></collision><inertial><origin
  rpy="0 0 0" xyz="0 0 0"/><mass value="2.414"/><inertia ixx="0.0023726" ixy="-3.0562e-06"
  ixz="-2.3418e-06" iyy="0.0023716" iyz="5.1202e-06" izz="0.0016667"/></inertial></link><link
  name="omnicam_forward"><inertial><origin rpy="0 0 0" xyz="0 0 0"/><mass value="1e-5"/><inertia
  ixx="1e-3" ixy="1e-6" ixz="1e-6" iyy="1e-3" iyz="1e-6" izz="1e-3"/></inertial></link><joint
  name="omnicam_j" type="fixed"><parent link="top_box"/><child link="omnicam"/><origin
  rpy="0 0 -1.2566370614359172" xyz="-0.0065 0 0.1655"/></joint><joint name="omnicam_forward_j"
  type="fixed"><parent link="omnicam"/><child link="omnicam_forward"/><origin rpy="0
  0 1.2566370614359172" xyz="0 0 0"/></joint><link name="omnicam_top"><inertial><origin
  rpy="0 0 0" xyz="0 0 0"/><mass value="1e-5"/><inertia ixx="1e-3" ixy="1e-6" ixz="1e-6"
  iyy="1e-3" iyz="1e-6" izz="1e-3"/></inertial></link><joint name="omnicam_top_j"
  type="fixed"><parent link="omnicam_forward"/><child link="omnicam_top"/><origin
  rpy="0 0 0" xyz="0 0 0.0685"/></joint><link name="omnicam_bottom"><inertial><origin
  rpy="0 0 0" xyz="0 0 0"/><mass value="1e-5"/><inertia ixx="1e-3" ixy="1e-6" ixz="1e-6"
  iyy="1e-3" iyz="1e-6" izz="1e-3"/></inertial></link><joint name="omnicam_bottom_j"
  type="fixed"><parent link="omnicam_forward"/><child link="omnicam_bottom"/><origin
  rpy="0 0 0" xyz="0 0 -0.0685"/></joint><link name="camera_0"><inertial><origin rpy="0
  0 0" xyz="0 0 0"/><mass value="1e-5"/><inertia ixx="1e-3" ixy="1e-6" ixz="1e-6"
  iyy="1e-3" iyz="1e-6" izz="1e-3"/></inertial></link><joint name="camera_0_j" type="fixed"><parent
  link="omnicam"/><child link="camera_0"/><origin rpy="-1.57174375606326 -0.0007844824059131495
  -1.5697029547363666" xyz="0.042087 -0.001706 -0.000359"/></joint><link name="camera_1"><inertial><origin
  rpy="0 0 0" xyz="0 0 0"/><mass value="1e-5"/><inertia ixx="1e-3" ixy="1e-6" ixz="1e-6"
  iyy="1e-3" iyz="1e-6" izz="1e-3"/></inertial></link><joint name="camera_1_j" type="fixed"><parent
  link="omnicam"/><child link="camera_1"/><origin rpy="-1.5718653069230086 0.0008525856465700664
  -2.8269565685229905" xyz="0.011469 -0.040128 -8.6e-05"/></joint><link name="camera_2"><inertial><origin
  rpy="0 0 0" xyz="0 0 0"/><mass value="1e-5"/><inertia ixx="1e-3" ixy="1e-6" ixz="1e-6"
  iyy="1e-3" iyz="1e-6" izz="1e-3"/></inertial></link><joint name="camera_2_j" type="fixed"><parent
  link="omnicam"/><child link="camera_2"/><origin rpy="-1.5725010220821427 0.0041503911916930475
  2.198063607332636" xyz="-0.034854 -0.022887 0.000521"/></joint><link name="camera_3"><inertial><origin
  rpy="0 0 0" xyz="0 0 0"/><mass value="1e-5"/><inertia ixx="1e-3" ixy="1e-6" ixz="1e-6"
  iyy="1e-3" iyz="1e-6" izz="1e-3"/></inertial></link><joint name="camera_3_j" type="fixed"><parent
  link="omnicam"/><child link="camera_3"/><origin rpy="-1.5713748741869842 0.005611132750385732
  0.9420078617362798" xyz="-0.033204 0.025729 0.000217"/></joint><link name="camera_4"><inertial><origin
  rpy="0 0 0" xyz="0 0 0"/><mass value="1e-5"/><inertia ixx="1e-3" ixy="1e-6" ixz="1e-6"
  iyy="1e-3" iyz="1e-6" izz="1e-3"/></inertial></link><joint name="camera_4_j" type="fixed"><parent
  link="omnicam"/><child link="camera_4"/><origin rpy="-1.5816111122187593 0.0010343402884573788
  -0.31479000897956244" xyz="0.014502 0.038991 -0.000301"/></joint><link name="camera_5"><inertial><origin
  rpy="0 0 0" xyz="0 0 0"/><mass value="1e-5"/><inertia ixx="1e-3" ixy="1e-6" ixz="1e-6"
  iyy="1e-3" iyz="1e-6" izz="1e-3"/></inertial></link><joint name="camera_5_j" type="fixed"><parent
  link="omnicam"/><child link="camera_5"/><origin rpy="0.003778346518059264 0.0007855787457013103
  -1.5719092456776718" xyz="0.000402 -0.000922 0.062128"/></joint></robot>

